#VRML_SIM R2022a utf8
WorldInfo {
}
Viewpoint {
  orientation 0.18185867803548508 0.07411432391041367 -0.9805276580568688 2.5331615274108454
  position 2.1369186977641217 1.3439998932235304 4.385436115874905
}
TexturedBackground {
  texture "mars"
}
TexturedBackgroundLight {
  luminosity 2
}
UnevenTerrain {
  appearance SandyGround {
    colorOverride 0.5 0.5 0.4
    textureTransform TextureTransform {
      scale 50 50
    }
  }
}
Robot {
  translation -0.5249471545758287 -0.04697527193130723 3.3537696357823177
  rotation 0.8432978521248897 -0.5374056911468641 -0.006622365476855846 0.08937143759295832
  children [
    DEF body Shape {
      appearance HammeredCopper {
      }
      geometry Box {
        size 0.7 0.5 0.2
      }
    }
    Solid {
      translation 0 0 0.19
      children [
        DEF panel Shape {
          appearance SolarCell {
          }
          geometry Box {
            size 0.8 0.5 0.01
          }
        }
        Solid {
          translation 0.3 -0.19 -0.05
          children [
            Shape {
              appearance Copper {
              }
              geometry Cylinder {
                height 0.1
                radius 0.02
              }
            }
          ]
          name "solar_panel_support1"
        }
        Solid {
          translation 0.3 0.19 -0.05
          children [
            Shape {
              appearance Copper {
              }
              geometry Cylinder {
                height 0.1
                radius 0.02
              }
            }
          ]
          name "solar_panel_support2"
        }
        Solid {
          translation -0.3 0.19 -0.05
          children [
            Shape {
              appearance Copper {
              }
              geometry Cylinder {
                height 0.1
                radius 0.02
              }
            }
          ]
          name "solar_panel_support3"
        }
        Solid {
          translation -0.3 -0.19 -0.05
          children [
            Shape {
              appearance Copper {
              }
              geometry Cylinder {
                height 0.1
                radius 0.02
              }
            }
          ]
          name "solar_panel_support4"
        }
      ]
      name "solar_panel"
    }
    Solid {
      translation -0.18 -0.24 0
      children [
        SliderJoint {
          jointParameters JointParameters {
            position -4.0529997960600914e-05
            minStop -0.1
            staticFriction 1
          }
          device [
            LinearMotor {
              name "linear1_left"
              maxForce 50
            }
          ]
          endPoint Solid {
            translation -0.00017985453301283538 -0.017342787906382884 0.06001075547265197
            rotation -0.9999999928695749 8.057119204137451e-05 -8.814268504930294e-05 1.5708453179831379
            children [
              DEF cylinder1 Shape {
                appearance DamascusSteel {
                }
                geometry Cylinder {
                  height 0.09
                  radius 0.02
                }
              }
              Solid {
                translation 0 0 -0.05
                children [
                  DEF sphere1 Shape {
                    appearance BrushedSteel {
                    }
                    geometry Sphere {
                      radius 0.02
                    }
                  }
                  Solid {
                    translation 0 0.1 1.79608e-07
                    rotation -1 0 0 -1.5707953071795862
                    children [
                      DEF cylinder2 Shape {
                        appearance BrushedSteel {
                        }
                        geometry Cylinder {
                          height 0.2
                          radius 0.02
                        }
                      }
                      Solid {
                        translation 0 0 -0.11
                        children [
                          DEF sphere1 Shape {
                            appearance BrushedSteel {
                            }
                            geometry Sphere {
                              radius 0.02
                            }
                          }
                          Solid {
                            translation 0 -0.03 -9.99999e-08
                            rotation 1 0 0 1.5708
                            children [
                              DEF cylinder3 Shape {
                                appearance BrushedSteel {
                                }
                                geometry Cylinder {
                                  height 0.06
                                  radius 0.02
                                }
                              }
                              HingeJoint {
                                jointParameters HingeJointParameters {
                                  position -4.627711693683841
                                  axis 0 0 1
                                  anchor -9.51224e-05 0.00113507 0.0800056
                                }
                                device [
                                  RotationalMotor {
                                    name "wheel1_left"
                                  }
                                ]
                                endPoint Solid {
                                  translation 0.0010047044632611754 0.0014814573240437326 0.08000499999999995
                                  rotation -7.565809690243949e-07 6.903835215701319e-07 -0.9999999999994755 4.627710539455526
                                  children [
                                    DEF wheel Shape {
                                      appearance DamascusSteel {
                                      }
                                      geometry Cylinder {
                                        height 0.15
                                        radius 0.15
                                      }
                                    }
                                  ]
                                  boundingObject USE wheel
                                  physics Physics {
                                    mass 1
                                  }
                                  linearVelocity -0.000403879409203531 -0.00012259822238433742 -6.9553887549244755e-06
                                  angularVelocity 0.0006380990109412326 -0.002578794338115282 -0.000159541043193514
                                }
                              }
                            ]
                            boundingObject USE cylinder3
                            physics DEF phy1 Physics {
                              mass 1
                            }
                          }
                        ]
                        name "solid(1)"
                        boundingObject USE sphere1
                        physics USE phy1
                      }
                    ]
                    boundingObject USE cylinder2
                    physics USE phy1
                  }
                ]
                boundingObject USE sphere1
                physics USE phy1
              }
            ]
            boundingObject USE cylinder1
            physics USE phy1
            linearVelocity -0.0006793095957080028 -0.00019438994866084454 4.485603684887117e-05
            angularVelocity 0.0006380292652555565 -0.0025844669022691714 -0.0001599633861325225
          }
        }
      ]
      name "wheel1_left_system"
      physics USE phy1
    }
    Solid {
      translation 0.18 -0.24 0
      children [
        SliderJoint {
          jointParameters JointParameters {
            position -1.4334874196480073e-05
            minStop -0.1
            staticFriction 1
          }
          device [
            LinearMotor {
              name "linear2_left"
              maxForce 50
            }
          ]
          endPoint Solid {
            translation -0.00017985453301283538 -0.017342787906382884 0.060036950596416096
            rotation -0.9999999928695749 8.057119204137451e-05 -8.814268504930294e-05 1.5708453179831379
            children [
              DEF cylinder1 Shape {
                appearance DamascusSteel {
                }
                geometry Cylinder {
                  height 0.09
                  radius 0.02
                }
              }
              Solid {
                translation 0 0 -0.05
                children [
                  DEF sphere1 Shape {
                    appearance BrushedSteel {
                    }
                    geometry Sphere {
                      radius 0.02
                    }
                  }
                  Solid {
                    translation 0 0.1 1.79608e-07
                    rotation -1 0 0 -1.5707953071795862
                    children [
                      DEF cylinder2 Shape {
                        appearance BrushedSteel {
                        }
                        geometry Cylinder {
                          height 0.2
                          radius 0.02
                        }
                      }
                      Solid {
                        translation 0 0 -0.11
                        children [
                          DEF sphere1 Shape {
                            appearance BrushedSteel {
                            }
                            geometry Sphere {
                              radius 0.02
                            }
                          }
                          Solid {
                            translation 0 -0.03 -9.99999e-08
                            rotation 1 0 0 1.5708
                            children [
                              DEF cylinder3 Shape {
                                appearance BrushedSteel {
                                }
                                geometry Cylinder {
                                  height 0.06
                                  radius 0.02
                                }
                              }
                              HingeJoint {
                                jointParameters HingeJointParameters {
                                  position 161.60576141005612
                                  axis 0 0 1
                                  anchor 0.000341778 0.000558794 0.0800055
                                }
                                device [
                                  RotationalMotor {
                                    name "wheel2_left"
                                  }
                                ]
                                endPoint Solid {
                                  translation -0.0001634169672139637 0.0008420206585510798 0.08000499999999995
                                  rotation -7.519435222258577e-07 -6.277779304393614e-07 -0.9999999999995202 1.7570554226729833
                                  children [
                                    DEF wheel Shape {
                                      appearance DamascusSteel {
                                      }
                                      geometry Cylinder {
                                        height 0.15
                                        radius 0.15
                                      }
                                    }
                                  ]
                                  boundingObject USE wheel
                                  physics Physics {
                                    mass 1
                                  }
                                  linearVelocity -0.00039914077258289244 -0.00011632644240403348 -7.942516012179745e-05
                                  angularVelocity 0.0006373121353603424 -0.002577718178821611 -0.0001596832039972909
                                }
                              }
                            ]
                            boundingObject USE cylinder3
                            physics DEF phy1 Physics {
                              mass 1
                            }
                          }
                        ]
                        name "solid(1)"
                        boundingObject USE sphere1
                        physics USE phy1
                      }
                    ]
                    boundingObject USE cylinder2
                    physics USE phy1
                  }
                ]
                boundingObject USE sphere1
                physics USE phy1
              }
            ]
            boundingObject USE cylinder1
            physics USE phy1
            linearVelocity -0.0006755530195172487 -0.0001875820090471092 -2.6072109156718133e-05
            angularVelocity 0.0006373916996557629 -0.0025843155839321654 -0.00016015415875234268
          }
        }
      ]
      name "wheel2_left_system"
      physics USE phy1
    }
    Solid {
      translation 0.18 0.24 0
      rotation 0 0 1 3.14159
      children [
        SliderJoint {
          jointParameters JointParameters {
            position -0.0011294858845557559
            minStop -0.1
            staticFriction 1
          }
          device [
            LinearMotor {
              name "linear2_right"
              maxForce 50
            }
          ]
          endPoint Solid {
            translation -0.00017985453301283538 -0.017342787906382884 0.05892179958605682
            rotation -0.9999999928695749 8.057119204137451e-05 -8.814268504930294e-05 1.5708453179831379
            children [
              DEF cylinder1 Shape {
                appearance DamascusSteel {
                }
                geometry Cylinder {
                  height 0.09
                  radius 0.02
                }
              }
              Solid {
                translation 0 0 -0.05
                children [
                  DEF sphere1 Shape {
                    appearance BrushedSteel {
                    }
                    geometry Sphere {
                      radius 0.02
                    }
                  }
                  Solid {
                    translation 0 0.1 1.79608e-07
                    rotation -1 0 0 -1.5707953071795862
                    children [
                      DEF cylinder2 Shape {
                        appearance BrushedSteel {
                        }
                        geometry Cylinder {
                          height 0.2
                          radius 0.02
                        }
                      }
                      Solid {
                        translation 0 0 -0.11
                        children [
                          DEF sphere1 Shape {
                            appearance BrushedSteel {
                            }
                            geometry Sphere {
                              radius 0.02
                            }
                          }
                          Solid {
                            translation 0 -0.03 -9.99999e-08
                            rotation 1 0 0 1.5708
                            children [
                              DEF cylinder3 Shape {
                                appearance BrushedSteel {
                                }
                                geometry Cylinder {
                                  height 0.06
                                  radius 0.02
                                }
                              }
                              HingeJoint {
                                jointParameters HingeJointParameters {
                                  position -244.31747762854928
                                  axis 0 0 1
                                  anchor 0.00034353 0.000611995 0.0800044
                                }
                                device [
                                  RotationalMotor {
                                    name "wheel2_right"
                                  }
                                ]
                                endPoint Solid {
                                  translation 0.0006041990086409123 3.8081632757467764e-05 0.08000499999999995
                                  rotation 0.35543059790073944 -0.9347026746916269 -4.91385045470772e-07 3.1415951189172393
                                  children [
                                    DEF wheel Shape {
                                      appearance DamascusSteel {
                                      }
                                      geometry Cylinder {
                                        height 0.15
                                        radius 0.15
                                      }
                                    }
                                  ]
                                  boundingObject USE wheel
                                  physics Physics {
                                    mass 1
                                  }
                                  linearVelocity -0.00042269453610992483 -0.00015396586983943246 0.0004340319592179161
                                  angularVelocity 0.0006352962167206436 -0.0025760700539679193 -0.00015980165392319575
                                }
                              }
                            ]
                            boundingObject USE cylinder3
                            physics DEF phy1 Physics {
                              mass 1
                            }
                          }
                        ]
                        name "solid(1)"
                        boundingObject USE sphere1
                        physics USE phy1
                      }
                    ]
                    boundingObject USE cylinder2
                    physics USE phy1
                  }
                ]
                boundingObject USE sphere1
                physics USE phy1
              }
            ]
            boundingObject USE cylinder1
            physics USE phy1
            linearVelocity -0.0006937418853714974 -0.00021561479912571012 0.0003544871912453315
            angularVelocity 0.0006353454935521575 -0.002583456169999947 -0.0001603391846552078
          }
        }
      ]
      name "wheel2_right_system"
      physics USE phy1
    }
    Solid {
      translation -0.18 0.24 0
      rotation 0 0 1 3.14159
      children [
        SliderJoint {
          jointParameters JointParameters {
            position -6.227917187290257e-06
            minStop -0.1
            staticFriction 1
          }
          device [
            LinearMotor {
              name "linear1_right"
              maxForce 50
            }
          ]
          endPoint Solid {
            translation -0.00017985453301283538 -0.017342787906382884 0.060045057553425284
            rotation -0.9999999928695749 8.057119204137451e-05 -8.814268504930294e-05 1.5708453179831379
            children [
              DEF cylinder1 Shape {
                appearance DamascusSteel {
                }
                geometry Cylinder {
                  height 0.09
                  radius 0.02
                }
              }
              Solid {
                translation 0 0 -0.05
                children [
                  DEF sphere1 Shape {
                    appearance BrushedSteel {
                    }
                    geometry Sphere {
                      radius 0.02
                    }
                  }
                  Solid {
                    translation 0 0.1 1.79608e-07
                    rotation -1 0 0 -1.5707953071795862
                    children [
                      DEF cylinder2 Shape {
                        appearance BrushedSteel {
                        }
                        geometry Cylinder {
                          height 0.2
                          radius 0.02
                        }
                      }
                      Solid {
                        translation 0 0 -0.11
                        children [
                          DEF sphere1 Shape {
                            appearance BrushedSteel {
                            }
                            geometry Sphere {
                              radius 0.02
                            }
                          }
                          Solid {
                            translation 0 -0.03 -9.99999e-08
                            rotation 1 0 0 1.5708
                            children [
                              DEF cylinder3 Shape {
                                appearance BrushedSteel {
                                }
                                geometry Cylinder {
                                  height 0.06
                                  radius 0.02
                                }
                              }
                              HingeJoint {
                                jointParameters HingeJointParameters {
                                  position 3.3382664272969382
                                  axis 0 0 1
                                  anchor 0.00034338 0.000576422 0.0800045
                                }
                                device [
                                  RotationalMotor {
                                    name "wheel1_right"
                                  }
                                ]
                                endPoint Solid {
                                  translation 0.0004154568136012117 0.0011684539206024821 0.08000499999999995
                                  rotation -0.9951687564696966 -0.09817915331081271 1.3152954218421807e-06 3.1415930022025256
                                  children [
                                    DEF wheel Shape {
                                      appearance DamascusSteel {
                                      }
                                      geometry Cylinder {
                                        height 0.15
                                        radius 0.15
                                      }
                                    }
                                  ]
                                  boundingObject USE wheel
                                  physics Physics {
                                    mass 1
                                  }
                                  linearVelocity -0.0003850364496934811 -8.864418492620476e-05 -0.00046448309362677156
                                  angularVelocity 0.0006398551754612534 -0.0025778006059025958 -0.0001596822278262261
                                }
                              }
                            ]
                            boundingObject USE cylinder3
                            physics DEF phy1 Physics {
                              mass 1
                            }
                          }
                        ]
                        name "solid(1)"
                        boundingObject USE sphere1
                        physics USE phy1
                      }
                    ]
                    boundingObject USE cylinder2
                    physics USE phy1
                  }
                ]
                boundingObject USE sphere1
                physics USE phy1
              }
            ]
            boundingObject USE cylinder1
            physics USE phy1
            linearVelocity -0.0006522534662175491 -0.0001484579653527347 -0.000562720420524199
            angularVelocity 0.0006399313403257735 -0.00258348949793401 -0.0001600914466634946
          }
        }
      ]
      name "wheel1_right_system"
      physics USE phy1
    }
  ]
  boundingObject USE body
  physics DEF phy Physics {
    mass 1
  }
  controller "sd"
  linearVelocity -0.0007774542106835581 -0.00019521947401928295 -0.0003039459967480849
  angularVelocity 0.0006377458976049644 -0.0025840428916318525 -0.00016014032975105515
}
